Workbook
Name _\D: #REF!
Name _\D: #REF!
Name _\X: #REF!
Name _\X: #REF!
Name _01: #REF!
Name _01: #REF!
Name _02: #REF!
Name _02: #REF!
Name _03: #REF!
Name _03: #REF!
Name _1: #REF!
Name _1: #REF!
Name _10: #N/A
Name _11: #N/A
Name _12: #N/A
Name _13: #N/A
Name _14: #N/A
Name _15: #N/A
Name _16: #N/A
Name _17: #N/A
Name _18: #N/A
Name _19: #N/A
Name _1공장: #REF!
Name _1공장: #REF!
Name _2: #N/A
Name _20: #N/A
Name _21: #N/A
Name _22: #N/A
Name _23: #N/A
Name _24: #N/A
Name _25: #N/A
Name _26: #N/A
Name _27: #N/A
Name _28: #N/A
Name _29: #N/A
Name _2공장: #REF!
Name _2공장: #REF!
Name _3: #REF!
Name _3: #REF!
Name _30: #N/A
Name _31: #N/A
Name _32: #N/A
Name _33: #N/A
Name _34: #N/A
Name _35: #N/A
Name _36: #N/A
Name _37: #N/A
Name _38: #N/A
Name _39: #N/A
Name _3공장: #REF!
Name _3공장: #REF!
Name _4: #REF!
Name _4: #REF!
Name _４._설___비____공___사: #REF!
Name _４._설___비____공___사: #REF!
Name _4_6_7: "a=evaluate(사진대지!B24)"
Name _40: #N/A
Name _41: #N/A
Name _42: #N/A
Name _43: #N/A

Sheet 갑 지
B2: TO.
A4: 見 積 書
A9: 工 事 名 :
A10: 工 事 名 :
A21: TO.
A23: 공 사 명/PROJECT :신당동 하이츠아파트 106동1303호 인테리어 공사
A25: 날 짜 / DATE : 2022 년 09월 2일.
A26: ="금 액/AMOUNT : 일금"&NUMBERSTRING(H51,1)&"원정(\"&TEXT(H51,"#,##)") -> 금 액/AMOUNT : 일금팔천칠백만원정(\87,000,000) | G26: (V.A.T 별도)
A27: 납품 또는 시공완료예정일/ESTIMATED DATE OF COMPLETION
A28: 착수보증금/DEPOSIT | G28: 회사명 :
A29: 납품 또는 시공장소/DESTINATION AND/OR CONSTRUCTION SITE | G29: 주 소 :
A30: 고객이름 및 서명/CLIENT'S NAME & SIGNATURE | G30: TEL/FAX:
G31: 대표자 : (인)
A32: 下記와 같이 견적합니다.
A35: NO | B35: 명 칭 | C35: 규 격 | D35: 단위 | E35: 수량 | F35: 재 료 비 | G35: 노 무 비 | H35: 총 액 | I35: 비 고
B36: 직접공사비
A37: Ⅰ | B37: 인테리어공사 | D37: 식 | E37: 1 | F37: =+내역!H20 -> 58104066 | G37: =+내역!J20 -> 16286235 | H37: =+내역!L20 -> 79139780
B39: 소계(A) | F39: =F37 -> 58104066 | G39: =G37 -> 16286235 | H39: =H37 -> 79139780
B41: 간접공사비
A42: Ⅱ | B42: A. 근재보험(노무비의 1.8%) | D42: 식 | E42: 1 | F42: =SUM(F40:F41) -> 0 | G42: 0 | H42: =+내역!L22 -> 0
A43: Ⅲ | B43: B. 기타경비(재료비+노무비의 3%) | D43: 식 | E43: 1 | F43: =SUM(F41:F42) -> 0 | G43: 0 | H43: =+내역!L23 -> 0
A44: Ⅳ | B44: C. 일반관리비(재료비+노무비의 2%) | D44: 식 | E44: 1 | F44: =SUM(F42:F43) -> 0 | G44: 0 | H44: =+내역!L24 -> 0
A45: Ⅴ | B45: D. 기업이윤(총액의 10%) | D45: 식 | E45: 1 | F45: =SUM(F43:F44) -> 0 | G45: 0 | H45: =+내역!L25 -> 7913978.1
B48: 소계(B) | F48: =F42+F43+F44+F45+F46 -> 0 | G48: =G42+G43+G44+G45+G46 -> 0 | H48: =SUM(H42:H47) -> 7913978.1
B50: 합계 | F50: =F39+F48 -> 58104066 | G50: =G39+G48 -> 16286235 | H50: =H39+H48 -> 87053759
G51: (단수정리) | H51: =TRUNC(H50,-5) -> 87000000
J55: 고객명 | M55: 연락처 | P55: 현장주소 | W55: 계약일
J57: 견적가 | K57: 일금 | L57: =NUMBERSTRING($U$37,1) -> 영 | P57: 원정 | Q57: ( \ | R57: =H50 -> 87053759 | T57: 원 ) | W57: 담당자

Sheet 내역
A1: 번호 | B1: 명칭 | C1: 규격 | D1: 스팩 | E1: 수량 | F1: 단위 | G1: 재료비 | I1: 노무비 | K1: 총액 | M1: 비고
A2: NO | B2: DESCRIPTION | C2: SIZE | D2: Spec. | E2: Q'TY | F2: UNIT | G2: 단가 | H2: 금액 | I2: 단가 | J2: 금액 | K2: 단가 | L2: 금액 | M2: REMARK
A3: ** | B3: 공 사 명:
A4: 1 | B4: 가설 공사 | E4: =1 -> 1 | F4: 식 | H4: =H39 -> 903975 | J4: =J39 -> 849540 | L4: =L39 -> 1753515
A5: 2 | B5: 철거,설비 공사 | E5: =1 -> 1 | F5: 식 | H5: =H56 -> 4046735 | J5: =J56 -> 2041130 | L5: =L56 -> 6087865
A6: 3 | B6: 목공 공사 | E6: =1 -> 1 | F6: 식 | H6: =H82 -> 5606000 | J6: =J82 -> 2800000 | L6: =L82 -> 8406000
A7: 4 | B7: 전기 공사 | E7: =1 -> 1 | F7: 식 | H7: =H112 -> 3250009 | J7: =J112 -> 1450000 | L7: =L112 -> 4700009
A8: 5 | B8: 도배 공사 | E8: =1 -> 1 | F8: 식 | H8: =H121 -> 1308611.5 | J8: =J121 -> 2250000 | L8: =L121 -> 3558611.5
A9: 6 | B9: 타일 공사 | E9: =1 -> 1 | F9: 식 | H9: =H135 -> 2656000 | J9: =J135 -> 2800000 | L9: =L135 -> 5456000
A10: 7 | B10: 욕실 공사 | E10: =1 -> 1 | F10: 식 | H10: =H164 -> 3851600 | J10: =J164 -> 500000 | L10: =L164 -> 4351600
A11: 8 | B11: 가구 공사 | E11: =1 -> 1 | F11: 식 | H11: =H169 -> 23220000 | J11: =J169 -> 1550000 | L11: =L169 -> 24770000
A12: 9 | B12: 샤시 공사 | E12: =1 -> 1 | F12: 식 | H12: =H189 -> 12977955 | J12: =J189 -> 1550000 | L12: =L189 -> 12977955
A13: 10 | B13: 도장 공사 | E13: =1 -> 1 | F13: 식 | H13: =H196 -> 283180 | J13: =J196 -> 495565 | L13: =L196 -> 778745
A14: 11 | B14: 마루 공사 | E14: =1 -> 1 | F14: 식 | H14: =H202 -> 3601280 | J14: =J199 -> 1059200 | L14: =L202 -> 4660480
A15: 12 | B15: 기타 공사 | E15: =1 -> 1 | F15: 식 | H15: =H214 -> 1376500 | J15: =J214 -> 262500 | L15: =L214 -> 1639000
B20: 직접공사비계 | H20: =SUM(H4:H13) -> 58104066 | J20: =SUM(J4:J13) -> 16286235 | L20: =SUM(L4:L15) -> 79139780
B22: A. 근재보험(노무비의 1.8%) | E22: =1 -> 1 | F22: 식 | H22: 0
B23: B. 기타경비(재료비+노무비의 3%) | E23: =1 -> 1 | F23: 식 | H23: 0
B24: C. 일반관리비(재료비+노무비의 2%) | E24: =1 -> 1 | F24: 식 | H24: 0
B25: D. 기업이윤(총액의 10%) | E25: =1 -> 1 | F25: 식 | H25: 0 | L25: =L20*10% -> 7913978.1
B26: 간접접공사비계 | H26: =SUM(E26:G26) -> 0 | J26: =SUM(G26:I26) -> 0 | L26: =SUM(L21:L25) -> 7913978.1
B27: 합계 | H27: =H20+H26 -> 58104066 | J27: =J20+J26 -> 16286235 | L27: =L20+L26 -> 87053759
K28: (단수정리) | L28: =TRUNC(L27,-5) -> 87000000
B29: **견적기준
B30: 1.관리소 예치금,견적외 제외
B31: 2.VAT별도.
A32: =A4 -> 1 | B32: =B4 -> 가설 공사 | N32: 실행
B33: 공사신고 및 동의서 | C33: 확장신고 대행 및 도면작성 | E33: 1 | F33: 식 | G33: 550000 | H33: =E33*G33 -> 550000 | J33: =E33*I33 -> 0 | K33: =G33+I33 -> 550000 | L33: =H33+J33 -> 550000
B34: 현장정리 | C34: ELV보양 포함 | D34: 기본 | E34: 141.59 | F34: M2 | G34: 1500 | H34: =E34*G34 -> 212385 | J34: =E34*I34 -> 0 | K34: =G34+I34 -> 1500 | L34: =H34+J34 -> 212385
B35: 준공청소 | E35: 141.59 | F35: M2 | G35: 1000 | H35: =E35*G35 -> 141590 | I35: 3000 | J35: =E35*I35 -> 424770 | K35: =G35+I35 -> 4000 | L35: =H35+J35 -> 566360
B36: 자재소운반 | E36: 141.59 | F36: M2 | H36: =E36*G36 -> 0 | I36: 1000 | J36: =E36*I36 -> 141590 | K36: =G36+I36 -> 1000 | L36: =H36+J36 -> 141590
B37: 자재대운반 | E37: 141.59 | F37: M2 | H37: =E37*G37 -> 0 | I37: 2000 | J37: =E37*I37 -> 283180 | K37: =G37+I37 -> 2000 | L37: =H37+J37 -> 283180
K38: =G38+I38 -> 0 | L38: =H38+J38 -> 0
B39: 소계 | H39: =SUM(H33:H38) -> 903975 | J39: =SUM(J33:J38) -> 849540 | L39: =SUM(L33:L38) -> 1753515
A41: =A5 -> 2 | B41: =B5 -> 철거,설비 공사
B42: 내부지정철거 | C42: 기본철거 | E42: 141.59 | F42: M2 | G42: 2500 | H42: =E42*G42 -> 353975 | I42: 7000 | J42: =E42*I42 -> 991130 | K42: =G42+I42 -> 9500 | L42: =H42+J42 -> 1345105
B43: 거실 확장 철거 | C43: 확장부위 전체 | E43: 1 | F43: 식 | G43: 150000 | H43: =E43*G43 -> 150000 | I43: 150000 | J43: =E43*I43 -> 150000 | K43: =G43+I43 -> 300000 | L43: =H43+J43 -> 300000
B44: 건너방 확장 철거 | C44: 확장부위 전체 | E44: 1 | F44: 식 | G44: 100000 | H44: =E44*G44 -> 100000 | I44: 150000 | J44: =E44*I44 -> 150000 | K44: =G44+I44 -> 250000 | L44: =H44+J44 -> 250000
B45: 화장실 철거 | C45: 기본철거 | E45: 2 | F45: 개소 | G45: 100000 | H45: =E45*G45 -> 200000 | I45: 150000 | J45: =E45*I45 -> 300000 | K45: =G45+I45 -> 250000 | L45: =H45+J45 -> 500000
B46: 바닥철거 | C46: 전체 철거 | E46: 105.92 | F46: M2 | G46: 3000 | H46: =E46*G46 -> 317760 | J46: =E46*I46 -> 0 | K46: =G46+I46 -> 3000 | L46: =H46+J46 -> 317760
...

Sheet 진환
A1: 번호 | B1: 명칭 | C1: 규격 | D1: 스팩 | E1: 수량 | F1: 단위 | G1: 재료비 | I1: 노무비 | K1: 총액 | M1: 비고
A2: NO | B2: DESCRIPTION | C2: SIZE | D2: Spec. | E2: Q'TY | F2: UNIT | G2: 단가 | H2: 금액 | I2: 단가 | J2: 금액 | K2: 단가 | L2: 금액 | M2: REMARK
A3: ** | B3: 공 사 명:
A4: 1 | B4: 가설 공사 | E4: =1 -> 1 | F4: 식 | H4: =H39 -> 903975 | J4: =J39 -> 849540 | L4: =L39 -> 1753515
A5: 2 | B5: 철거,설비 공사 | E5: =1 -> 1 | F5: 식 | H5: =H56 -> 4046735 | J5: =J56 -> 2041130 | L5: =L56 -> 6087865
A6: 3 | B6: 목공 공사 | E6: =1 -> 1 | F6: 식 | H6: =H82 -> 3351000 | J6: =J82 -> 2800000 | L6: =L82 -> 6151000
A7: 4 | B7: 전기 공사 | E7: =1 -> 1 | F7: 식 | H7: =H112 -> 2030009 | J7: =J112 -> 1450000 | L7: =L112 -> 3480009
A8: 5 | B8: 도배 공사 | E8: =1 -> 1 | F8: 식 | H8: =H121 -> 499919 | J8: =J121 -> 2250000 | L8: =L121 -> 2749919
A9: 6 | B9: 타일 공사 | E9: =1 -> 1 | F9: 식 | H9: =H135 -> 2656000 | J9: =J135 -> 2800000 | L9: =L135 -> 5456000
A10: 7 | B10: 욕실 공사 | E10: =1 -> 1 | F10: 식 | H10: =H164 -> 920000 | J10: =J164 -> 500000 | L10: =L164 -> 1420000
A11: 8 | B11: 가구 공사 | E11: =1 -> 1 | F11: 식 | H11: =H169 -> 0 | J11: =J169 -> 0 | L11: =L169 -> 0
A12: 9 | B12: 샤시 공사 | E12: =1 -> 1 | F12: 식 | H12: =H189 -> 13158955 | J12: =J189 -> 0 | L12: =L189 -> 13158955
A13: 10 | B13: 도장 공사 | E13: =1 -> 1 | F13: 식 | H13: =H196 -> 283180 | J13: =J196 -> 495565 | L13: =L196 -> 778745
A14: 11 | B14: 마루 공사 | E14: =1 -> 1 | F14: 식 | H14: =H202 -> 0 | J14: =J199 -> 0 | L14: =L202 -> 0
A15: 12 | B15: 기타 공사 | E15: =1 -> 1 | F15: 식 | H15: =H214 -> 1376500 | J15: =J214 -> 262500 | L15: =L214 -> 1639000
B20: 직접공사비계 | H20: =SUM(H4:H13) -> 27849773 | J20: =SUM(J4:J13) -> 13186235 | L20: =SUM(L4:L15) -> 42675008
B22: A. 근재보험(노무비의 1.8%) | E22: =1 -> 1 | F22: 식 | H22: 0
B23: B. 기타경비(재료비+노무비의 3%) | E23: =1 -> 1 | F23: 식 | H23: 0
B24: C. 일반관리비(재료비+노무비의 2%) | E24: =1 -> 1 | F24: 식 | H24: 0
B25: D. 기업이윤(총액의 10%) | E25: =1 -> 1 | F25: 식 | H25: 0 | L25: =L20*10% -> 4267500.8
B26: 간접접공사비계 | H26: =SUM(E26:G26) -> 0 | J26: =SUM(G26:I26) -> 0 | L26: =SUM(L21:L25) -> 4267500.8
B27: 합계 | H27: =H20+H26 -> 27849773 | J27: =J20+J26 -> 13186235 | L27: =L20+L26 -> 46942509
K28: (단수정리) | L28: =TRUNC(L27,-5) -> 46900000
B29: **견적기준
B30: 1.관리소 예치금,견적외 제외
B31: 2.VAT별도.
A32: =A4 -> 1 | B32: =B4 -> 가설 공사 | N32: 실행
B33: 공사신고 및 동의서 | C33: 확장신고 대행 및 도면작성 | E33: 1 | F33: 식 | G33: 550000 | H33: =E33*G33 -> 550000 | J33: =E33*I33 -> 0 | K33: =G33+I33 -> 550000 | L33: =H33+J33 -> 550000
B34: 현장정리 | C34: ELV보양 포함 | D34: 기본 | E34: 141.59 | F34: M2 | G34: 1500 | H34: =E34*G34 -> 212385 | J34: =E34*I34 -> 0 | K34: =G34+I34 -> 1500 | L34: =H34+J34 -> 212385
B35: 준공청소 | E35: 141.59 | F35: M2 | G35: 1000 | H35: =E35*G35 -> 141590 | I35: 3000 | J35: =E35*I35 -> 424770 | K35: =G35+I35 -> 4000 | L35: =H35+J35 -> 566360
B36: 자재소운반 | E36: 141.59 | F36: M2 | H36: =E36*G36 -> 0 | I36: 1000 | J36: =E36*I36 -> 141590 | K36: =G36+I36 -> 1000 | L36: =H36+J36 -> 141590
B37: 자재대운반 | E37: 141.59 | F37: M2 | H37: =E37*G37 -> 0 | I37: 2000 | J37: =E37*I37 -> 283180 | K37: =G37+I37 -> 2000 | L37: =H37+J37 -> 283180
K38: =G38+I38 -> 0 | L38: =H38+J38 -> 0
B39: 소계 | H39: =SUM(H33:H38) -> 903975 | J39: =SUM(J33:J38) -> 849540 | L39: =SUM(L33:L38) -> 1753515
A41: =A5 -> 2 | B41: =B5 -> 철거,설비 공사
B42: 내부지정철거 | C42: 기본철거 | E42: 141.59 | F42: M2 | G42: 2500 | H42: =E42*G42 -> 353975 | I42: 7000 | J42: =E42*I42 -> 991130 | K42: =G42+I42 -> 9500 | L42: =H42+J42 -> 1345105
B43: 거실 확장 철거 | C43: 확장부위 전체 | E43: 1 | F43: 식 | G43: 150000 | H43: =E43*G43 -> 150000 | I43: 150000 | J43: =E43*I43 -> 150000 | K43: =G43+I43 -> 300000 | L43: =H43+J43 -> 300000
B44: 건너방 확장 철거 | C44: 확장부위 전체 | E44: 1 | F44: 식 | G44: 100000 | H44: =E44*G44 -> 100000 | I44: 150000 | J44: =E44*I44 -> 150000 | K44: =G44+I44 -> 250000 | L44: =H44+J44 -> 250000
B45: 화장실 철거 | C45: 기본철거 | E45: 2 | F45: 개소 | G45: 100000 | H45: =E45*G45 -> 200000 | I45: 150000 | J45: =E45*I45 -> 300000 | K45: =G45+I45 -> 250000 | L45: =H45+J45 -> 500000
B46: 바닥철거 | C46: 전체 철거 | E46: 105.92 | F46: M2 | G46: 3000 | H46: =E46*G46 -> 317760 | J46: =E46*I46 -> 0 | K46: =G46+I46 -> 3000 | L46: =H46+J46 -> 317760
...
