Workbook

Sheet 갑지
B3: <RH대리점용>
B6: 2020 HANSSEM STYLE PACKAGE ESTIMATE VER 2.0
B8: 공 사 견 적 서 / ESTIMATE
B9: [ ]
B10: 제 출 처/To
B12: 공 사 명 /Project
B14: 견 적 일 자/Date | D14: =TODAY() -> 44244
B16: 금 액/Amount | D16: ="일금 "&NUMBERSTRING(E18,1)&"원 정" -> 일금 일천사백오십일만구천구백원 정
D18: ( | E18: =을지!K19 -> 14519900 | G18: ) 대리점 공급가 VAT 별도
B21: 별첨 명세와 같이 견적합니다. / We are pleased to submit you our estimate as specified on attached sheet(s).
B23: 견적조건/Terms | J23: RH대리점 :
J24: 담당 RD : | M24: (인)
B25: - 한샘外공사 견적금액 | Y25: 계약확정 서명란
B26: - 현장상황에 따른 시공금액변동 가능
B27: - 추가 작업 발생시 금액 사전 협의 후 진행 원칙 | P27: 공사확정 서명란
J28: 시공협력사 : | P28: 대리점 서명
J29: 대표이사 : | M29: (인)
B31: 비 고/Remark
B33: - 계약 확정 시 공사확정 서명란에 날인 후 한샘관리자에게 회신 원칙 | J33: 한샘관리자 : | M33: (인)
B34: - 최초견적금액 공사완료여부 관계없이 해달월 DR부과 원칙
B35: - 현장실측 후 D+2일내 견적서 전달 원칙
B53: 천장목공

Sheet 을지
B4: JOB NO | D4: 항목 | E4: 기준 | F4: 단위 | G4: 수량 | L4: 비 고
H5: 자재비 | I5: 노무비 | J5: 경비 | K5: 합계
B6: 1 | C6: 기본공사비
B7: 가 | D7: 기본공사비 | H7: =SUM(견적상세!L78,견적상세!L87,견적상세!L95,견적상세!L103,견적상세!L131,견적상세!L148,견적상세!L160,견적상세!L203,견적상세!L174,견적상세!L165,견적상세!L213) -> 2035576 | I7: =SUM(견적상세!N78,견적상세!N87,견적상세!N95,견적상세!N103,견적상세!N131,견적상세!N148,견적상세!N160,견적상세!N203,견적상세!N174,견적상세!N165,견적상세!N213) -> 11348976 | K7: =SUM(견적상세!O78,견적상세!O87,견적상세!O95,견적상세!O103,견적상세!O131,견적상세!O148,견적상세!O160,견적상세!O203,견적상세!O174,견적상세!O165,견적상세!O213) -> 13384552
D8: 공사관리비 | E8: 20,000/평 | F8: 평 | G8: 30 | J8: 20000 | K8: =J8*G8 -> 600000
C9: SUB-TOTAL | K9: =SUM(K7:K8) -> 13984552
B11: 2 | C11: 간접공사비
D12: 산재/고용보험료 | E12: 노무비의 4.67% | F12: % | G12: 4.67
D13: 공과잡비 | E13: 대리점 지급단가의 4% | F13: % | G13: 4 | H13: =H7*4% -> 81423.04 | I13: =I7*4% -> 453959.04 | K13: =H13+I13 -> 535382.08
C14: SUB-TOTAL | H14: =SUM(H12:H13) -> 81423.04 | I14: =SUM(I12:I13) -> 453959.04 | J14: =SUM(J12:J13) -> 0 | K14: =SUM(K12:K13) -> 535382.08
C16: T O T A L | K16: =K9+K14 -> 14519934
D18: 단수 조정
D19: 합 계 | K19: =TRUNC(K16,-2) -> 14519900
B20: 가 | C20: =C6 -> 기본공사비
B21: 1 | D21: =견적상세!C7 -> 철거 | F21: LOT | G21: 1 | H21: =견적상세!L78 -> 0 | I21: =견적상세!N78 -> 1637900 | K21: =H21+I21 -> 1637900
B22: 2 | D22: =견적상세!C79 -> 설비 | F22: LOT | G22: 1 | H22: =견적상세!L87 -> 0 | I22: =견적상세!N87 -> 96000 | K22: =H22+I22 -> 96000
B23: 3 | D23: 확장 | F23: LOT | G23: 1 | H23: =견적상세!L95 -> 864000 | I23: =견적상세!N95 -> 1080000 | K23: =H23+I23 -> 1944000
B24: 4 | D24: =견적상세!C96 -> 단열 | F24: LOT | G24: 1 | H24: =견적상세!L103 -> 0 | I24: =견적상세!N103 -> 0 | K24: =H24+I24 -> 0 | P24: =M24+N24 -> 0
B25: 5 | D25: =견적상세!C104 -> 목공 | F25: LOT | G25: 1 | H25: =견적상세!L131 -> 273600 | I25: =견적상세!N131 -> 1196500 | K25: =H25+I25 -> 1470100 | P25: =M25+N25 -> 0
B26: 6 | D26: =견적상세!C132 -> 전기/조명 | F26: LOT | G26: 1 | H26: =견적상세!L148 -> 338600 | I26: =견적상세!N148 -> 1541000 | K26: =H26+I26 -> 1879600 | P26: =M26+N26 -> 0
B27: 7 | D27: =견적상세!C149 -> 타일 | F27: LOT | G27: 1 | H27: =견적상세!L160 -> 0 | I27: =견적상세!N160 -> 1056000 | K27: =H27+I27 -> 1056000 | P27: =M27+N27 -> 0
B28: 8 | D28: 도배 | F28: LOT | G28: 1 | H28: =견적상세!L165 -> 319376 | I28: =견적상세!N165 -> 1568576 | K28: =H28+I28 -> 1887952 | P28: =M28+N28 -> 0
B29: 9 | D29: =견적상세!C166 -> 도장 | F29: LOT | G29: 1 | H29: =견적상세!L174 -> 240000 | I29: =견적상세!N174 -> 750000 | K29: =H29+I29 -> 990000 | P29: =M29+N29 -> 0
B30: 10 | D30: 필름 | F30: LOT | G30: 1 | H30: =견적상세!L203 -> 0 | I30: =견적상세!N203 -> 1868000 | K30: =H30+I30 -> 1868000 | P30: =M30+N30 -> 0
B31: 11 | D31: =견적상세!C204 -> 기타 | F31: LOT | G31: 1 | H31: =견적상세!L213 -> 0 | I31: =견적상세!N213 -> 555000 | K31: =H31+I31 -> 555000 | P31: =M31+N31 -> 0
D32: 합 계 | H32: =SUM(H21:H31) -> 2035576 | I32: =SUM(I21:I31) -> 11348976 | K32: =SUM(K21:K31) -> 13384552 | P32: =SUM(P21:P31) -> 0

Sheet 견적상세
B4: JOB NO | C4: 항 목 | D4: 항 목 | F4: 기 준 | G4: 오더번호 | H4: 단위 | I4: 수량 | P4: 비 고
E5: 기준 | K5: 자 재 비 | M5: 노 무 비 | O5: 총액
K6: 단가 | L6: 계 | M6: 단가 | N6: 계 | O6: 총계 | R6: 재료비 | S6: 노무비
B7: 1 | C7: 철거 | D7: 철거
B8: 부엌 철거 | C8: 부엌철거_ㅡ자, ㄱ자(3.5M 미만) [단위 : set] | D8: ㅡ자, ㄱ자(3.5M 미만) [단위 : set] | E8: 3.5M 이하 ㄱ부엌 1세트 기준 [키큰장 포함] | F8: - ㅡ자 부엌, ㄱ자 부엌 3.5M 이하 | H8: set | I8: 1 | J8: =IFERROR(VLOOKUP(C8,[1]Sheet2!$A:$B,2,0),"") -> 65000 | K8: =T8 -> 0 | L8: =K8*I8 -> 0 | M8: 65000 | N8: =M8*I8 -> 65000 | O8: =N8+L8 -> 65000 | R8: 0 | S8: 80000 | T8: 0 | U8: 80000
C9: 부엌철거_ㅡ자, ㄱ자(5M 미만) [단위 : set] | D9: ㅡ자, ㄱ자(5M 미만) [단위 : set] | E9: 5M 이하 ㄱ부엌 1세트 기준 [키큰장 포함] | F9: - ㅡ자 부엌, ㄱ자 부엌 5M 이하 | H9: set | J9: =IFERROR(VLOOKUP(C9,[1]Sheet2!$A:$B,2,0),"") -> 80000 | K9: =T9 -> 0 | L9: =K9*I9 -> 0 | M9: 80000 | N9: =M9*I9 -> 0 | O9: =N9+L9 -> 0
C10: 부엌철거_ㅡ자, ㄱ자(5M 이상) [단위 : set] | D10: ㅡ자, ㄱ자(5M 이상) [단위 : set] | E10: 5M 이상 ㄱ부엌 1세트 기준 [키큰장 포함] | F10: - ㄱ자 부엌 5M 이상 | H10: set | J10: =IFERROR(VLOOKUP(C10,[1]Sheet2!$A:$B,2,0),"") -> 90000 | K10: =T10 -> 0 | L10: =K10*I10 -> 0 | M10: =U10 -> 90000 | N10: =M10*I10 -> 0 | O10: =N10+L10 -> 0 | R10: 0 | S10: 90000 | T10: 0 | U10: 90000
C11: 부엌철거_ㄷ자, ㅁ자, 병렬형(12M 미만) [단위 : set] | D11: ㄷ자, ㅁ자, 병렬형(12M 미만) [단위 : set] | E11: 12M 이하 ㄷ부엌 1세트 기준 [키큰장 포함] | F11: - ㄷ자, ㅁ자, 병렬 부엌 12M 이하 | H11: set | J11: =IFERROR(VLOOKUP(C11,[1]Sheet2!$A:$B,2,0),"") -> 120000 | K11: =T11 -> 0 | L11: =K11*I11 -> 0 | M11: =U11 -> 120000 | N11: =M11*I11 -> 0 | O11: =N11+L11 -> 0 | R11: 0 | S11: 120000 | T11: 0 | U11: 120000
C12: 부엌철거_ㄷ자, ㅁ자, 병렬형(12M 이상) [단위 : set] | D12: ㄷ자, ㅁ자, 병렬형(12M 이상) [단위 : set] | E12: 12M 이상 ㅁ부엌 1세트 기준 [키큰장 포함] | F12: - ㄷ자, ㅁ자, 병렬 부엌 12M 이상 | H12: set | J12: =IFERROR(VLOOKUP(C12,[1]Sheet2!$A:$B,2,0),"") -> 140000 | K12: =T12 -> 0 | L12: =K12*I12 -> 0 | M12: 140000 | N12: =M12*I12 -> 0 | O12: =N12+L12 -> 0
C13: 부엌철거_아일랜드 [단위 : set] | D13: 아일랜드 [단위 : set] | E13: 독립형 단독 아일랜드 1세트 기준 (카운터 타입 아일랜드 대상아님, M포함) | F13: - 독립형 단독 아일랜드 1세트 기준(카운터 타입 아일랜드 대상아님, M포함) | H13: set | J13: =IFERROR(VLOOKUP(C13,[1]Sheet2!$A:$B,2,0),"") -> 30000 | K13: =T13 -> 0 | L13: =K13*I13 -> 0 | M13: 30000 | N13: =M13*I13 -> 0 | O13: =N13+L13 -> 0
C14: 부엌철거_발코니 보조주방 [단위 : set] | D14: 발코니 보조주방 [단위 : set] | E14: 발코니 보조주방 1세트 기준 | F14: - 발코니 보조주방 1세트기준 | H14: set | J14: =IFERROR(VLOOKUP(C14,[1]Sheet2!$A:$B,2,0),"") -> 30000 | K14: =T14 -> 0 | L14: =K14*I14 -> 0 | M14: 30000 | N14: =M14*I14 -> 0 | O14: =N14+L14 -> 0 | R14: 0 | S14: 140000 | T14: 0 | U14: 140000
C15: 부엌철거_옵션기기류 [단위 : EA] | D15: 옵션기기류 [단위 : EA] | E15: 식기세척기, 프리스텐딩오븐, 빌트인 오븐, 세탁기, 세척기 등 (후드, 쿡탑, 싱크볼, 수전, 쌀통, 벽장부착형 식기건조기 제외) | F15: - 식기세척기,프리스탠딩오븐,빌트인오븐,세탁기,세척기등(후드,쿡탑,싱크볼,수전,쌀통,벽장부착형EA기건조기제외) | H15: EA | J15: =IFERROR(VLOOKUP(C15,[1]Sheet2!$A:$B,2,0),"") -> 10000 | K15: =T15 -> 0 | L15: =K15*I15 -> 0 | M15: =U15 -> 10000 | N15: =M15*I15 -> 0 | O15: =N15+L15 -> 0 | R15: 0 | S15: 10000 | T15: 0 | U15: 10000
C16: 부엌철거_입수전 공사 [단위 : EA] | D16: 입수전 공사 [단위 : EA] | E16: 1m 미만 / 기존면 입수전 내림설비 기준 | F16: - 1m 미만, 기존면 입수전 내림설비 기준 | H16: EA | J16: =IFERROR(VLOOKUP(C16,[1]Sheet2!$A:$B,2,0),"") -> 70000 | K16: =T16 -> 0 | L16: =K16*I16 -> 0 | M16: 70000 | N16: =M16*I16 -> 0 | O16: =L16+N16 -> 0 | R16: 0 | S16: 70000 | T16: 0 | U16: 84000
B17: 수납 철거 | C17: 수납철거_현관장 [단위 : EA] | D17: 현관장 [단위 : EA] | E17: 현관장 도어 1개 기준 / 하프신발장은 50% 적용 | F17: - 현관장도어1개기준/하프신발장은50%적용 | H17: EA | I17: 3 | J17: =IFERROR(VLOOKUP(C17,[1]Sheet2!$A:$B,2,0),"") -> 10000 | K17: =T17 -> 0 | L17: =K17*I17 -> 0 | M17: =U17 -> 10000 | N17: =M17*I17 -> 30000 | O17: =N17+L17 -> 30000 | R17: 0 | S17: 10000 | T17: 0 | U17: 10000
C18: 수납철거_붙박이장, 이동장, 장롱 [단위 : EA] | D18: 붙박이장, 이동장, 장롱 [단위 : EA] | E18: 붙박이장, 이동장, 장롱 도어 1개 기준 / 슬라이딩 도어 개당 2개 산정 | F18: - 벽박이장문틀, 문선, 문짝 철거 포함 도어1개기준/미장별도 | H18: EA | J18: =IFERROR(VLOOKUP(C18,[1]Sheet2!$A:$B,2,0),"") -> 12000 | K18: =T18 -> 0 | L18: =K18*I18 -> 0 | M18: 12000 | N18: =M18*I18 -> 0 | O18: =N18+L18 -> 0 | R18: 0 | S18: 15000 | T18: 0 | U18: 15000
C19: 수납철거_벽박이장, 창고장 [단위 : EA] | D19: 벽박이장, 창고장 [단위 : EA] | E19: 벽박이장 문틀, 문선, 문짝철거 포함 도어 1개 기준 / 미장 별도 | F19: - 거실장 1m이하 기준/높이 850mm 이상 상하길이 적용(x2) | H19: M | J19: =IFERROR(VLOOKUP(C19,[1]Sheet2!$A:$B,2,0),"") -> 15000 | K19: =T19 -> 0 | L19: =K19*I19 -> 0 | M19: 15000 | N19: =M19*I19 -> 0 | O19: =N19+L19 -> 0 | R19: 12000 | S19: =R19*O19 -> 0 | T19: 0 | U19: 10000
C20: 수납철거_거실장 [단위 : M] | D20: 거실장 [단위 : M] | E20: 거실장 1M이하 기준 / 높이 850mm 이상 상하길이 적용 (x2) | F20: - 1.5m이하 빌트인 화장대 기준(일반 화장대 기타 단품장 1만적용) | H20: EA | J20: =IFERROR(VLOOKUP(C20,[1]Sheet2!$A:$B,2,0),"") -> 10000 | K20: =T20 -> 0 | L20: =K20*I20 -> 0 | M20: 10000 | N20: =M20*I20 -> 0 | O20: =N20+L20 -> 0 | R20: 36000 | S20: =R20*O20 -> 0 | T20: 0 | U20: 30000
C21: 수납철거_빌트인 화장대 [단위 : EA] | D21: 빌트인 화장대 [단위 : EA] | E21: 1.5M이하 빌트인 화장대 기준 (일반 화장대 기타 단품장 1만 적용) | F21: - | H21: EA | J21: =IFERROR(VLOOKUP(C21,[1]Sheet2!$A:$B,2,0),"") -> 30000 | K21: =T21 -> 0 | L21: =K21*I21 -> 0 | M21: 30000 | N21: =M21*I21 -> 0 | O21: =N21+L21 -> 0
C22: 수납철거_기타단품장 [단위 : EA] | D22: 기타항목기입 | R22: 0 | S22: 10000 | T22: 0 | U22: 10000
B23: 바닥 철거 | C23: 바닥철거_마루(본드접착식) [단위 : 평] | D23: 마루(본드접착식) [단위 : 평] | E23: 합판마루, 강마루, 원목마루 1평 기준 (최소진입비 25만) / ex}실측면적 기준 25평의 경우 25EA 수량 발주 / 본드제거, 바닥면 정리 | F23: - 합판마루, 강마루, 원목마루 1평기준(최소진입비25만)/ex)25평의 경우 25ea수량발주 | H23: 평 | I23: 19 | J23: =IFERROR(VLOOKUP(C23,[1]Sheet2!$A:$B,2,0),"") -> 23000 | K23: =T23 -> 0 | L23: =K23*I23 -> 0 | M23: 23000 | N23: =M23*I23 -> 437000 | O23: =N23+L23 -> 437000 | R23: 8364 | S23: =R23*O23 -> 3655068000 | T23: 0 | U23: 6970
C24: 바닥철거_강화마루 [단위 : 평] | D24: 강화마루 [단위 : 평] | E24: 강화마루 1평 기준 / 최소진입비 25만 / ex} 25평의 경우 25EA 수량 발주 | F24: - 강화마루 1평기준(최소진입비25만)/ex)25평의 경우 25ea수량발주 | H24: 평 | J24: =IFERROR(VLOOKUP(C24,[1]Sheet2!$A:$B,2,0),"") -> 15200 | K24: =T24 -> 0 | L24: =K24*I24 -> 0 | M24: 15200 | N24: =M24*I24 -> 0 | O24: =N24+L24 -> 0 | R24: 5454 | S24: =R24*O24 -> 0 | T24: 0 | U24: 4600
C25: 바닥철거_데코타일 [단위 : 평] | D25: 데코타일 [단위 : 평] | E25: 테코타일 1평 기준 / 최소진입비 25만 / ex} 25평의 경우 25EA 수량 발주 | F25: - 데코타일 1평기준(최소진입비25만)/ex)25평의 경우 25ea수량발주 | H25: 평 | J25: =IFERROR(VLOOKUP(C25,[1]Sheet2!$A:$B,2,0),"") -> 15200 | K25: =T25 -> 0 | L25: =K25*I25 -> 0 | M25: 15200 | N25: =M25*I25 -> 0 | O25: =N25+L25 -> 0 | R25: 5454 | S25: =R25*O25 -> 0 | T25: 0 | U25: 4600
C26: 바닥철거_장판 (방1개 기준) [단위 : EA] | D26: 장판 (방1개 기준) [단위 : EA] | E26: 방1개 기준 / 이중장판시 2개 적용 / 거실,주방 개별 실로 구분 | F26: - 방1개기준 / 이중장판시 2개 적용 | H26: EA | I26: 3 | J26: =IFERROR(VLOOKUP(C26,[1]Sheet2!$A:$B,2,0),"") -> 10000 | K26: =T26 -> 0 | L26: =K26*I26 -> 0 | M26: =U26 -> 10000 | N26: =M26*I26 -> 30000 | O26: =N26+L26 -> 30000 | R26: 12000 | S26: =R26*O26 -> 360000000 | T26: 0 | U26: 10000
C27: 바닥철거_폴리싱타일 [단위 : 평] | D27: 폴리싱타일 [단위 : 평] | E27: 폴리싱타일 1평 기준 / 최소진입비 25만 / ex} 10평의 경우 10EA 수량 발주 | F27: - 폴리싱타일 1평기준(최소진입비25만)/ex)10평의 경우 10ea수량발주 | H27: 평 | J27: =IFERROR(VLOOKUP(C27,[1]Sheet2!$A:$B,2,0),"") -> 40000 | K27: =T27 -> 0 | L27: =K27*I27 -> 0 | M27: 40000 | N27: =M27*I27 -> 0 | O27: =N27+L27 -> 0 | R27: 14545.2 | S27: =R27*O27 -> 0 | T27: 0 | U27: 12000
C28: 바닥철거_바탕작업(한지장판샌딩) [단위 : EA] | D28: 바탕작업(한지장판샌딩) [단위 : 평] | E28: 한지 장판 경우 | F28: - 방1개기준 | H28: 평 | J28: =IFERROR(VLOOKUP(C28,[1]Sheet2!$A:$B,2,0),"") -> 10000 | K28: =T28 -> 0 | L28: =K28*I28 -> 0 | M28: =U28 -> 10000 | N28: =M28*I28 -> 0 | O28: =N28+L28 -> 0 | R28: 12000 | S28: =R28*O28 -> 0 | T28: 0 | U28: 10000
C29: 바닥철거_바탕작업(바닥샌딩) [단위 : 평] | D29: 바탕작업(바닥샌딩) [단위 : 평] | E29: 실간 바닥 단차가 발생 경우, 바닥 평활도가 심하게 차이나는 경우 (현장점검) | F29: - | H29: 평 | J29: =IFERROR(VLOOKUP(C29,[1]Sheet2!$A:$B,2,0),"") -> 5000 | K29: =T29 -> 0 | L29: =K29*I29 -> 0 | M29: 5000 | N29: =M29*I29 -> 0 | O29: =N29+L29 -> 0
C30: 바닥철거_바탕작업(프라이머, 급결) [단위 : 평] | D30: 바탕작업(프라이머, 급결) [단위 : 평] | E30: 황토/모래질 바닥 인 경우 | F30: - 전용면적 기준 | H30: 평 | J30: =IFERROR(VLOOKUP(C30,[1]Sheet2!$A:$B,2,0),"") -> 7000 | K30: =T30 -> 0 | L30: =K30*I30 -> 0 | M30: 7000 | N30: =M30*I30 -> 0 | O30: =N30+L30 -> 0 | R30: 2545.2 | S30: =R30*O30 -> 0 | T30: 0 | U30: 2120
B31: 창호 철거 | C31: 창호철거_거실분합창 [단위 : EA] | D31: 거실분합창 [단위 : EA] | E31: 거실분합창 1틀기준 / 창호팀 철거 예외분만 해당 [확장시 선철거 필요] | F31: - 1틀기준 / 창호팀 철거 예외분만 해당 (확장시 선철거 필요) | H31: EA | I31: 1 | J31: =IFERROR(VLOOKUP(C31,[1]Sheet2!$A:$B,2,0),"") -> 100000 | K31: =T31 -> 0 | L31: =K31*I31 -> 0 | M31: =U31 -> 100000 | N31: =M31*I31 -> 100000 | O31: =N31+L31 -> 100000 | R31: 0 | S31: 100000 | T31: 0 | U31: 100000
C32: 창호철거_작은방분합창 [단위 : EA] | D32: 작은방분합창 [단위 : EA] | E32: 작은방분합창 1틀기준 / 창호팀 철거 예외분만 해당 [확장시 선철거 필요] | F32: - 1틀기준 / 창호팀 철거 예외분만 해당 (확장시 선철거 필요) | H32: EA | I32: 2 | J32: =IFERROR(VLOOKUP(C32,[1]Sheet2!$A:$B,2,0),"") -> 80000 | K32: =T32 -> 0 | L32: =K32*I32 -> 0 | M32: =U32 -> 80000 | N32: =M32*I32 -> 160000 | O32: =N32+L32 -> 160000 | R32: 0 | S32: 80000 | T32: 0 | U32: 80000
B33: 목공 철거 | C33: 목공철거_몰딩 [단위 : 평] | D33: 몰딩 [단위 : 평] | E33: 몰딩철거 1평 기준 / ex) 공급면적평수 32평 = 32EA 수량 발주 | F33: - 1평기준 / 공급면적평수 32평 = 32EA수량발주 | H33: 평 | I33: 36 | J33: =IFERROR(VLOOKUP(C33,[1]Sheet2!$A:$B,2,0),"") -> 1700 | K33: =T33 -> 0 | L33: =K33*I33 -> 0 | M33: 1700 | N33: =M33*I33 -> 61200 | O33: =N33+L33 -> 61200 | R33: 840 | S33: =R33*O33 -> 51408000 | T33: 0 | U33: 700
C34: 목공철거_걸레받이 [단위 : 평] | D34: 걸레받이 [단위 : 평] | E34: 걸레받이철거 1평 기준 / ex) 공급면적평수 32평 = 32EA 수량 발주 | F34: - 1평기준 / 공급면적평수 32평 = 32EA수량발주 | H34: 평 | I34: 36 | J34: =IFERROR(VLOOKUP(C34,[1]Sheet2!$A:$B,2,0),"") -> 1700 | K34: =T34 -> 0 | L34: =K34*I34 -> 0 | M34: 1700 | N34: =M34*I34 -> 61200 | O34: =N34+L34 -> 61200 | R34: 0 | S34: 700 | T34: 0 | U34: 700
C35: 목공철거_도어(문틀, 문짝, 문선, 인방 포함) [단위 : set] | D35: 도어(문틀, 문짝, 문선, 인방 포함) [단위 : set] | E35: 도어 1세트 기준 [문틀, 문짝, 문선, 인방 포함 / 3방, 4방 동일] | F35: - 도어1세트기준[문틀, 문짝, 문턱, 문선, 인방 포함/3방,4방동일] | H35: set | J35: =IFERROR(VLOOKUP(C35,[1]Sheet2!$A:$B,2,0),"") -> 30000 | K35: =T35 -> 0 | L35: =K35*I35 -> 0 | M35: =U35 -> 30000 | N35: =M35*I35 -> 0 | O35: =N35+L35 -> 0 | R35: 0 | S35: 30000 | T35: 0 | U35: 30000
C36: 목공철거_도어(문짝만 철거) [단위 : EA] | D36: 도어(문짝만 철거) [단위 : EA] | E36: 도어 문짝철거 1개 기준 | F36: - 도어 문짝철거 1개 기준 | H36: EA | J36: =IFERROR(VLOOKUP(C36,[1]Sheet2!$A:$B,2,0),"") -> 10000 | K36: =T36 -> 0 | L36: =K36*I36 -> 0 | M36: =U36 -> 10000 | N36: =M36*I36 -> 0 | O36: =N36+L36 -> 0 | R36: 0 | S36: 10000 | T36: 0 | U36: 10000
C37: 목공철거_도어(문선만 철거) [단위 : EA] | D37: 도어(문선만 철거) [단위 : EA] | E37: 도어 문선철거 1개 기준 | F37: - 도어 문선철거 1개 기준 | H37: EA | J37: =IFERROR(VLOOKUP(C37,[1]Sheet2!$A:$B,2,0),"") -> 5000 | K37: =T37 -> 0 | L37: =K37*I37 -> 0 | M37: 5000 | N37: =M37*I37 -> 0 | O37: =N37+L37 -> 0
C38: 목공철거_문턱제거(문턱철거, 문턱미장 포함) [단위 : EA] | D38: 문턱제거(문턱철거, 문턱미장 포함) [단위 : EA] | E38: 도어 문턱철거 1개 기준 / 문턱철거, 문턱미장 포함시 | F38: - 도어 문턱철거 1개 기준 / 문턱철거, 문턱미장 포함시 | H38: EA | J38: =IFERROR(VLOOKUP(C38,[1]Sheet2!$A:$B,2,0),"") -> 30000 | K38: =T38 -> 0 | L38: =K38*I38 -> 0 | M38: =U38 -> 30000 | N38: =M38*I38 -> 0 | O38: =N38+L38 -> 0 | R38: 0 | S38: 25000 | T38: 0 | U38: 30000
C39: 목공철거_문턱미장(문턱미장만 작업) [단위 : EA] | D39: 문턱미장(문턱미장만 작업) [단위 : EA] | E39: 도어 문턱미장 1개 기준, 미장만 작업시 | F39: - 도어 문턱 미장 1개 기준, 미장만 작업시 | H39: EA | J39: =IFERROR(VLOOKUP(C39,[1]Sheet2!$A:$B,2,0),"") -> 10000 | K39: =T39 -> 0 | L39: =K39*I39 -> 0 | M39: =U39 -> 10000 | N39: =M39*I39 -> 0 | O39: =N39+L39 -> 0 | R39: 0 | S39: 10000 | T39: 0 | U39: 10000
C40: 목공철거_중문 [단위 : set] | D40: 중문 [단위 : set] | E40: 중문철거 1세트 기준 (종류,길이 상관없음) | F40: - 중문철거 1세트 기준(종류,길이 상관없음) | H40: set | J40: =IFERROR(VLOOKUP(C40,[1]Sheet2!$A:$B,2,0),"") -> 60000 | K40: =T40 -> 0 | L40: =K40*I40 -> 0 | M40: =U40 -> 60000 | N40: =M40*I40 -> 0 | O40: =N40+L40 -> 0 | R40: 0 | S40: 50000 | T40: 0 | U40: 60000
C41: 목공철거_천장철거 우물천장 [단위 : set] | D41: 천장철거 우물천장 [단위 : set] | E41: 우물천장 철거 1세트 기준 | F41: - 우물천장 철거 1세트 기준 | H41: set | I41: 1 | J41: =IFERROR(VLOOKUP(C41,[1]Sheet2!$A:$B,2,0),"") -> 100000 | K41: =T41 -> 0 | L41: =K41*I41 -> 0 | M41: =U41 -> 100000 | N41: =M41*I41 -> 100000 | O41: =N41+L41 -> 100000 | R41: 0 | S41: 100000 | T41: 0 | U41: 100000
C42: 목공철거_천장철거 천장등박스 [단위 : set] | D42: 천장철거 천장등박스 [단위 : set] | E42: 등박스 목공철거 1세트 기준 (사이즈 무관) | F42: - 등박스 목공철거 1세트 기준(사이즈무관) | H42: set | J42: =IFERROR(VLOOKUP(C42,[1]Sheet2!$A:$B,2,0),"") -> 30000 | K42: =T42 -> 0 | L42: =K42*I42 -> 0 | M42: =U42 -> 30000 | N42: =M42*I42 -> 0 | O42: =N42+L42 -> 0 | R42: 0 | S42: 30000 | T42: 0 | U42: 30000
C43: 목공철거_천장철거 전체 [단위 : 평] | D43: 천장철거 전체 [단위 : 평] | E43: 천장 전체철거 (우물천장 포함) 1평당 기준 | F43: - 천장 전체철거(우물천장포함)1평당기준 | H43: 평 | J43: =IFERROR(VLOOKUP(C43,[1]Sheet2!$A:$B,2,0),"") -> 15000 | K43: =T43 -> 0 | L43: =K43*I43 -> 0 | M43: =U43 -> 15000 | N43: =M43*I43 -> 0 | O43: =N43+L43 -> 0 | R43: 0 | S43: 15000 | T43: 0 | U43: 15000
...

Sheet 추가항목기입
B4: 추가 사항 세부 내용 기입
